Workbook

Sheet Data2019+
A1: Archie-Plot
B2: N3 | G2: N4
A3: Date | B3: NMR water content | C3: std | D3: resistivity | E3: location | F3: Date | G3: NMR water content | H3: std | I3: resistivity | J3: location
A4: 43760 | B4: 0.11 | C4: 0.0202 | D4: 23.9674 | E4: top | F4: 43761 | G4: 0.084 | H4: 0.0181 | I4: 34.8879 | J4: top
B5: 0.1084 | C5: 0.0017 | D5: 25.04 | E5: bottom | G5: 0.0952 | H5: 0.0165 | I5: 16.704 | J5: bottom
A6: 43762 | B6: 0.1039 | C6: 0.0253 | D6: 24.0093 | E6: top | F6: 43893 | G6: 0.0805 | H6: 0.0207 | I6: 50.3304 | J6: top
B7: 0.1108 | C7: 0.0059 | D7: 25.0461 | E7: bottom | G7: 0.0769 | H7: 0.0029 | I7: 57.5492 | J7: bottom
A8: 43893 | B8: 0.1033 | C8: 0.0226 | D8: 34.569 | E8: top | F8: 44091 | G8: 0.1086 | H8: 0.0123 | I8: 36.1543 | J8: bottom
B9: 0.1007 | C9: 0.0058 | D9: 53.0637 | E9: bottom | F9: 44274 | G9: 0.0929 | H9: 0.01 | I9: 58.6893 | J9: top
A10: 44091 | B10: 0.1239 | C10: 0.0084 | D10: 32.1216 | E10: bottom | G10: 0.0866 | H10: 0.0096 | I10: 55.7404 | J10: bottom
A11: 44274 | B11: 0.1302 | C11: 0.0299 | D11: 22.8053 | E11: top | F11: 44475 | G11: 0.145 | H11: 0.0101 | I11: 32.1539 | J11: top
B12: 0.1279 | C12: 0.0095 | D12: 29.9979 | E12: bottom | G12: 0.1289 | H12: 0.0092 | I12: 37.5512 | J12: bottom
A13: 44476 | B13: 0.1608 | C13: 0.0154 | D13: 22.9194 | E13: top | G13: 0.1395 | H13: 0.0089 | I13: 38.7188 | J13: left
B14: 0.1528 | C14: 0.01 | D14: 29.187 | E14: bottom | G14: 0.13 | H14: 0.0127 | I14: 51.0851 | J14: right
B15: 0.1584 | C15: 0.0145 | D15: 21.0753 | E15: left | F15: 44644 | G15: 0.0935 | H15: 0.0135 | I15: 59.2389 | J15: top
B16: 0.1535 | C16: 0.0161 | D16: 21.2119 | E16: right | G16: 0.108 | H16: 0.0165 | I16: 57.7041 | J16: bottom
A17: 44679 | B17: 0.1716 | C17: 0.0127 | D17: 22.6024 | E17: top | G17: 0.1073 | H17: 0.0135 | I17: 93.9979 | J17: left
B18: 0.1502 | C18: 0.0076 | D18: 29.2163 | E18: bottom | G18: 0.0752 | H18: 0.0169 | I18: 169.185 | J18: right
B19: 0.1521 | C19: 0.009 | D19: 21.8003 | E19: left | F19: 44853 | G19: 0.0977 | H19: 0.0101 | I19: 43.6639 | J19: top
B20: 0.1509 | C20: 0.0088 | D20: 21.3087 | E20: right | G20: 0.1199 | H20: 0.0103 | I20: 42.1851 | J20: bottom
A21: 44854 | B21: 0.1456 | C21: 0.0148 | D21: 22.675 | E21: top | G21: 0.1368 | H21: 0.0099 | I21: 48.0418 | J21: left
B22: 0.1461 | C22: 0.0069 | D22: 28.4451 | E22: bottom | G22: 0.1058 | H22: 0.0108 | I22: 73.9692 | J22: right
B23: 0.1494 | C23: 0.0074 | D23: 21.1636 | E23: left | F23: 44979 | G23: 0.0904 | H23: 0.0242 | I23: 65.1749 | J23: top
B24: 0.1368 | C24: 0.0087 | D24: 21.188 | E24: right | G24: 0.0981 | H24: 0.0201 | I24: 51.0722 | J24: bottom
A25: 44980 | B25: 0.1482 | C25: 0.015 | D25: 22.2173 | E25: top | G25: 0.1105 | H25: 0.0197 | I25: 87.4335 | J25: left
B26: 0.1489 | C26: 0.0126 | D26: 28.4015 | E26: bottom | G26: 0.0997 | H26: 0.0319 | I26: 185.919 | J26: right
B27: 0.1638 | C27: 0.0146 | D27: 21.6869 | E27: left | F27: 45251 | G27: 0.0986 | H27: 0.0151 | I27: 47.2217 | J27: top
B28: 0.1485 | C28: 0.0147 | D28: 21.3081 | E28: right | G28: 0.1027 | H28: 0.0133 | I28: 50.6086 | J28: bottom
A29: 45252 | B29: 0.1693 | C29: 0.0184 | D29: 22.44 | E29: top | G29: 0.1148 | H29: 0.0124 | I29: 53.2272 | J29: left
B30: 0.1533 | C30: 0.0158 | D30: 27.933 | E30: bottom | G30: 0.1119 | H30: 0.0172 | I30: 96.5072 | J30: right
B31: 0.1558 | C31: 0.0169 | D31: 21.1969 | E31: left | F31: 45609 | G31: 0.1352 | H31: 0.0581 | I31: 41.0608 | J31: top
B32: 0.1299 | C32: 0.0103 | D32: 21.1526 | E32: right | G32: 0.1179 | H32: 0.0165 | I32: 40.7119 | J32: bottom
A33: 45610 | B33: 0.1678 | C33: 0.0181 | D33: 23.0637 | E33: top | G33: 0.15 | H33: 0.0517 | I33: 43.7826 | J33: left
B34: 0.1481 | C34: 0.014 | D34: 28.621 | E34: bottom | G34: 0.1251 | H34: 0.0261 | I34: 62.7552 | J34: right
B35: 0.1593 | C35: 0.0177 | D35: 21.2328 | E35: left | F35: 45700 | G35: 0.0897 | H35: 0.0288 | I35: 53.6506 | J35: top
B36: 0.1557 | C36: 0.0159 | D36: 21.2702 | E36: right | G36: 0.094 | H36: 0.0213 | I36: 57.6056 | J36: bottom
A37: 45701 | B37: 0.1328 | C37: 0.0438 | D37: 22.9968 | E37: top | G37: 0.1105 | H37: 0.0229 | I37: 79.8745 | J37: left
B38: 0.1524 | C38: 0.0163 | D38: 28.728 | E38: bottom | G38: 0.1006 | H38: 0.0183 | I38: 193.597 | J38: right
B39: 0.1498 | C39: 0.0223 | D39: 21.6306 | E39: left
B40: 0.1467 | C40: 0.0264 | D40: 21.2447 | E40: right
...

Sheet open-closed

Sheet sidewalls

Sheet top-bottom

Sheet Tabelle1
A1: ERT data is missing:
A3: Nische 4 | B3: Nische 3
A4: open niche | B4: closed niche
B5: 44679
A6: 44853 | B6: 44854
A7: 44979 | B7: 44980
A8: 45251 | B8: 45252
A9: 45609 | B9: 45610
A10: 45700 | B10: 45701

Sheet Kruschwitz2004
A1: water content | B1: saturation | C1: cond. | D1: resistivity | F1: Model Data2019+ | G1: old fit
A2: 0.01 | B2: =A2/0.15 -> 0.066666667 | C2: =$B$24*POWER(B2,1.72)*POWER(0.15,1.38)+0.11*POWER(B2,0.4) -> 0.039098376 | D2: =1/C2 -> 25.57651 | F2: =1.108*POWER(Kruschwitz2004!A2,-1.58) -> 1601.5473 | G2: =1.6866*POWER(Kruschwitz2004!A2,-1.325) -> 753.37655
A3: =0.01+A2 -> 0.02 | B3: =A3/0.15 -> 0.13333333 | C3: =$B$24*POWER(B3,1.72)*POWER(0.15,1.38)+0.11*POWER(B3,0.4) -> 0.055269698 | D3: =1/C3 -> 18.093097 | F3: =1.108*POWER(Kruschwitz2004!A3,-1.58) -> 535.68855 | G3: =1.6866*POWER(Kruschwitz2004!A3,-1.325) -> 300.70964
A4: =0.01+A3 -> 0.03 | B4: =A4/0.15 -> 0.2 | C4: =$B$24*POWER(B4,1.72)*POWER(0.15,1.38)+0.11*POWER(B4,0.4) -> 0.070110475 | D4: =1/C4 -> 14.263204 | F4: =1.108*POWER(Kruschwitz2004!A4,-1.58) -> 282.28524 | G4: =1.6866*POWER(Kruschwitz2004!A4,-1.325) -> 175.72212
A5: =0.01+A4 -> 0.04 | B5: =A5/0.15 -> 0.26666667 | C5: =$B$24*POWER(B5,1.72)*POWER(0.15,1.38)+0.11*POWER(B5,0.4) -> 0.08504904 | D5: =1/C5 -> 11.757922 | F5: =1.108*POWER(Kruschwitz2004!A5,-1.58) -> 179.17812 | G5: =1.6866*POWER(Kruschwitz2004!A5,-1.325) -> 120.02801
A6: =0.01+A5 -> 0.05 | B6: =A6/0.15 -> 0.33333333 | C6: =$B$24*POWER(B6,1.72)*POWER(0.15,1.38)+0.11*POWER(B6,0.4) -> 0.10056119 | D6: =1/C6 -> 9.944194 | F6: =1.108*POWER(Kruschwitz2004!A6,-1.58) -> 125.941 | G6: =1.6866*POWER(Kruschwitz2004!A6,-1.325) -> 89.305219
A7: =0.01+A6 -> 0.06 | B7: =A7/0.15 -> 0.4 | C7: =$B$24*POWER(B7,1.72)*POWER(0.15,1.38)+0.11*POWER(B7,0.4) -> 0.11685511 | D7: =1/C7 -> 8.5576062 | F7: =1.108*POWER(Kruschwitz2004!A7,-1.58) -> 94.419302 | G7: =1.6866*POWER(Kruschwitz2004!A7,-1.325) -> 70.139342
A8: =0.01+A7 -> 0.07 | B8: =A8/0.15 -> 0.46666667 | C8: =$B$24*POWER(B8,1.72)*POWER(0.15,1.38)+0.11*POWER(B8,0.4) -> 0.13403387 | D8: =1/C8 -> 7.4608007 | F8: =1.108*POWER(Kruschwitz2004!A8,-1.58) -> 74.009055 | G8: =1.6866*POWER(Kruschwitz2004!A8,-1.325) -> 57.181717
A9: =0.01+A8 -> 0.08 | B9: =A9/0.15 -> 0.53333333 | C9: =$B$24*POWER(B9,1.72)*POWER(0.15,1.38)+0.11*POWER(B9,0.4) -> 0.15215135 | D9: =1/C9 -> 6.572403 | F9: =1.108*POWER(Kruschwitz2004!A9,-1.58) -> 59.931836 | G9: =1.6866*POWER(Kruschwitz2004!A9,-1.325) -> 47.909084
A10: =0.01+A9 -> 0.09 | B10: =A10/0.15 -> 0.6 | C10: =$B$24*POWER(B10,1.72)*POWER(0.15,1.38)+0.11*POWER(B10,0.4) -> 0.17123574 | D10: =1/C10 -> 5.8399025 | F10: =1.108*POWER(Kruschwitz2004!A10,-1.58) -> 49.754985 | G10: =1.6866*POWER(Kruschwitz2004!A10,-1.325) -> 40.986494
A11: =0.01+A10 -> 0.1 | B11: =A11/0.15 -> 0.66666667 | C11: =$B$24*POWER(B11,1.72)*POWER(0.15,1.38)+0.11*POWER(B11,0.4) -> 0.19130077 | D11: =1/C11 -> 5.2273704 | F11: =1.108*POWER(Kruschwitz2004!A11,-1.58) -> 42.124985 | G11: =1.6866*POWER(Kruschwitz2004!A11,-1.325) -> 35.646106
A12: =0.01+A11 -> 0.11 | B12: =A12/0.15 -> 0.73333333 | C12: =$B$24*POWER(B12,1.72)*POWER(0.15,1.38)+0.11*POWER(B12,0.4) -> 0.21235169 | D12: =1/C12 -> 4.7091689 | F12: =1.108*POWER(Kruschwitz2004!A12,-1.58) -> 36.235922 | G12: =1.6866*POWER(Kruschwitz2004!A12,-1.325) -> 31.41715
A13: =0.01+A12 -> 0.12 | B13: =A13/0.15 -> 0.8 | C13: =$B$24*POWER(B13,1.72)*POWER(0.15,1.38)+0.11*POWER(B13,0.4) -> 0.23438852 | D13: =1/C13 -> 4.2664205 | F13: =1.108*POWER(Kruschwitz2004!A13,-1.58) -> 31.581546 | G13: =1.6866*POWER(Kruschwitz2004!A13,-1.325) -> 27.996062
A14: =0.01+A13 -> 0.13 | B14: =A14/0.15 -> 0.86666667 | C14: =$B$24*POWER(B14,1.72)*POWER(0.15,1.38)+0.11*POWER(B14,0.4) -> 0.25740803 | D14: =1/C14 -> 3.8848828 | F14: =1.108*POWER(Kruschwitz2004!A14,-1.58) -> 27.829747 | G14: =1.6866*POWER(Kruschwitz2004!A14,-1.325) -> 25.178923
... A19: =0.01+A18 -> 0.18 | B19: =A19/0.15 -> 1.2 | C19: =$B$24*POWER(B19,1.72)*POWER(0.15,1.38)+0.11*POWER(B19,0.4) -> 0.38702505 | D19: =1/C19 -> 2.5838121 | F19: =1.108*POWER(Kruschwitz2004!A19,-1.58) -> 16.642141 | G19: =1.6866*POWER(Kruschwitz2004!A19,-1.325) -> 16.359726
A23: fluid cond [mS/cm] | B23: 26.92
A24: [S/m] | B24: =B23/1000*100 -> 2.692
A25: fluid resistivity [Ohm*m] | B25: =1/B24 -> 0.37147103
